Workbook

Sheet LEIA-ME
A1: Municípios do Brasil — IBGE
A2: Gerado em | B2: 29/10/2026 16:14 por build_municipios_ibge.py (pipeline reprodutível; fontes e hashes na aba Fontes).
A3: Cobertura | B3: 5.571 municípios (DTB 2025, que inclui Brasília/DF e o Distrito Estadual de Fernando de Noronha/PE, codificado pelo IBGE como município) · 10.751 distritos · 510 Regiões Geográficas Imediatas · 133 Intermediárias · 27 UFs.
A5: ABAS
A6: Municipios | B6: 1 linha por município: códigos, UF, regiões imediata e intermediária, coordenada da sede (com fonte, status e observação), distritos, centroide e ponto interno do polígono.
A7: Distritos | B7: 1 linha por distrito (tabela plana): distrito + município + UF + regiões + coordenada do município e da sede distrital.
A8: Regioes_Imediatas / Regioes_Intermediarias / UFs | B8: Dimensões para modelo estrela (Power BI).
A9: Resumo_UF | B9: Contagens por UF com fórmulas vivas (COUNTIF/COUNTIFS/SUM).
A10: Auditoria_Coordenadas | B10: 130 municípios: 112 com divergência > 5 km entre fontes, 14 com o ponto 2022 a ≥ 3 km das duas referências e os demais por status ≠ OK, precisão de minuto, sede na borda do limite, sede junto à de outro distrito ou curadoria — com os valores de cada fonte e a decisão.
A11: Validacao | B11: 61 checagens automáticas do pipeline + 11 checagens com fórmula viva.
A12: Fontes | B12: Produto IBGE, safra, origem do arquivo, endereço oficial e SHA-256 de cada insumo.
A14: COORDENADAS — O QUE SIGNIFICAM
A15: Latitude / Longitude | B15: Ponto oficial da SEDE MUNICIPAL (área urbana da sede) do IBGE — Localidades do Brasil 2022 (categoria 'Cidade' / 'Sede Municipal'). Graus decimais, datum SIRGAS 2000 (EPSG:4674). Município é uma área; este é o ponto de referência oficial da cidade-sede, padrão para mapas de pontos, distâncias e geocodificação. Não é necessariamente a prefeitura nem o marco zero.
A16: Precisão | B16: O IBGE publica os atributos de 2022 com 4 casas decimais (≈ 11 m). Os pontos IBGE 2010 têm precisão total (gravados com 6 casas, ≈ 0,1 m).
A17: Regra de correção | B17: O ponto IBGE 2022 é substituído pelo IBGE 2010 quando diverge > 5 km (> 10 km nas capitais, de área urbana extensa) de DUAS fontes independentes ao mesmo tempo (IBGE 2010 e a base comunitária kelvins). A observação registra a evidência: o ponto 2022 coincide com outra localidade (povoado, vila) ou está isolado. Também usa o 2010 quando o ponto 2022 foi arredondado ao minuto de arco. Resultado: 15 municípios corrigidos (ex.: Manicoré/AM, cujo ponto 2022 estava 237 km deslocado), dos quais 2 ainda 'a conferir' (Porto Velho, Boca do Acre). Além disso, União da Serra/RS manteve o ponto 2022 e está marcado 'a conferir'. 14 pontos 2022 mantidos a ≥ 3 km das duas referências (que concordam entre si) estão anotados na observação.
A18: Curadoria | B18: 8 municípios têm nota de curadoria documentada (status e/ou referência externa, com a distância calculada pelo pipeline); a coordenada continua sendo um ponto oficial do IBGE. Inclui as capitais: Porto Velho, São Paulo.
A19: Validação geométrica | B19: Todas as sedes foram testadas contra o polígono do próprio município (Malha Municipal IBGE 2025). 'Na borda' = até 1 km fora, efeito da simplificação da malha.
A20: Centroide x Ponto Interno | B20: Centroide = centro de massa do polígono (pode cair fora em municípios côncavos; ilhas oceânicas a > 50 km ficam de fora, ex.: Trindade/Martim Vaz em Vitória). Ponto interno = polo de inacessibilidade, sempre dentro. Entre si diferem em mediana 2,8 km (p25 1,4; p75 5,6); a sede fica em mediana a 5,5 km do centroide.
A21: Grandes cidades | B21: Em metrópoles o ponto IBGE da sede é um ponto representativo da área urbana e pode ficar a alguns km do centro histórico (ex.: em São Paulo o ponto fica a 5,6 km da Praça da Sé). Para análises intramunicipais, use distritos ou setores censitários.
A23: DISTRITOS
A24: Distrito-sede | B24: Convenção do IBGE: o distrito-sede recebe o sufixo 05 — validado: 5.564 das 5.565 sedes IBGE 2010 estão no distrito 05; a exceção é São Paulo/SP, com 96 distritos numerados 01–96 sem sede codificada ('Não se aplica'). Em 2 municípios o distrito-sede tem nome diferente do município (renomeações): São Vicente do Seridó/PB (sede 'Seridó'), União da Serra/RS (sede 'São Luiz').
A25: Coordenada do distrito | B25: Distrito-sede = sede municipal. Demais distritos, nesta ordem: ponto 'Vila' (sede distrital) do IBGE Localidades 2022 (GO, SC, AM, AP, PA, RR) → 'Vila' do IBGE 2010 → localidade IBGE homônima e única no município (povoado, núcleo etc.). Cada ponto só é aceito se cair dentro do próprio município. Isso reprovou 2 pontos — p.ex. a Vila 2022 de Marcílio Dias (-2,1355; -50,3903), que caía fora do município. Cobertura: 10.256 de 10.751 distritos (95,4%). Sem coordenada: 380: distrito criado após 2010 (sem ponto IBGE 2022 nos arquivos disponíveis, que cobrem só GO, SC, AM, AP, PA e RR) · 95: distrito urbano: o IBGE não publica ponto de sede para estes distritos · 13: distrito já existia em 2010, mas sem ponto 'Vila' no cadastro IBGE 2010 · 6: sem ponto 'Vila' no IBGE Localidades 2022 · 1: ponto disponível reprovado no teste de limite municipal. O motivo está na coluna Observação de cada linha.
A27: NOMES OFICIAIS
A28: Correção de codificação | B28: O IBGE publica 9 regiões (8 nomes distintos) com o caractere U+00BF (ponto de interrogação invertido) no lugar do travessão — defeito replicado pela API. Normalizados para ' - ': 'Belo Jardim [U+00BF] Pesqueira' → 'Belo Jardim - Pesqueira'; 'Goiana [U+00BF] Timbaúba' → 'Goiana - Timbaúba'; 'Pão de Açúcar - Olho d'Água das Flores [U+00BF] Batalha' → 'Pão de Açúcar - Olho d'Água das Flores - Batalha'; 'Ilhéus [U+00BF] Itabuna' → 'Ilhéus - Itabuna'; 'Nazaré [U+00BF] Maragogipe' → 'Nazaré - Maragogipe'; 'Xique-Xique [U+00BF] Barra' → 'Xique-Xique - Barra'; 'São Joaquim da Barra [U+00BF] Orlândia' → 'São Joaquim da Barra - Orlândia'; 'Cornélio Procópio [U+00BF] Bandeirantes' → 'Cornélio Procópio - Bandeirantes'.
A29: Grafias das regiões | B29: Os nomes das regiões seguem a grafia oficial da DTB, que às vezes difere da grafia atual do município homônimo (ex.: 'Juíz de Fora', 'Açu', 'Itapagé'). Relacione sempre por código.
A30: Dígito verificador | B30: 9 códigos oficiais não satisfazem o algoritmo do DV (2201919, 2201988, 2202251, 2611533, 3117836, 3152131, 4305871, 5203939, 5203962). São válidos.
A32: USO E ATUALIZAÇÃO
A33: Power BI — modelo | B33: Importe tbl_Municipios, tbl_Distritos, tbl_Regioes_Imediatas, tbl_Regioes_Intermediarias e tbl_UFs e desligue a detecção automática de relacionamentos. Relacione (N:1): Distritos[Código IBGE] → Municipios[Código IBGE]; Municipios[Código Região Imediata] → Regioes_Imediatas; Regioes_Imediatas[Código Região Intermediária] → Regioes_Intermediarias; Regioes_Intermediarias[Código UF] → UFs. Marque Latitude/Longitude com a categoria de dados correspondente, colunas de código como 'Não resumir' e use 'Município - UF' em filtros e rótulos (há nomes repetidos).
A34: Como atualizar | B34: Baixe as novas edições oficiais do IBGE (DTB, Localidades, Malha Municipal — endereços na aba Fontes), substitua os arquivos no diretório de fontes e rode: python build_municipios_ibge.py --fontes <dir> --saida <dir>. Se qualquer validação crítica falhar, o resultado vai para Municipios_Brasil_IBGE_FALHOU.xlsx (log em build_log_FALHOU.txt) e o arquivo anterior não é sobrescrito. Para pandas, leia a aba Resumo_UF com nrows=27 (a linha de total fica abaixo da tabela).

Sheet Municipios
A1: Código IBGE | B1: Código IBGE (6 dígitos) | C1: Município | D1: Município - UF | E1: UF | F1: Código UF | G1: Estado | H1: Região | I1: Código Região Intermediária | J1: Região Geográfica Intermediária | K1: Código Região Imediata | L1: Região Geográfica Imediata | M1: Latitude | N1: Longitude | O1: Fonte da Coordenada | P1: Status da Coordenada | Q1: Capital (Sim/Não) | R1: Qtd. Distritos | S1: Código Distrito-Sede | T1: Nome do Distrito-Sede | U1: Distritos | V1: Sede dentro do Limite Municipal | W1: Observação da Coordenada | X1: Latitude Centroide | Y1: Longitude Centroide | Z1: Centroide dentro do Município | AA1: Latitude Ponto Interno | AB1: Longitude Ponto Interno
A2: 1100015 | B2: 110001 | C2: Alta Floresta D'Oeste | D2: Alta Floresta D'Oeste - RO | E2: RO | F2: 11 | G2: Rondônia | H2: Norte | I2: 1102 | J2: Ji-Paraná | K2: 110005 | L2: Cacoal | M2: -11.933 | N2: -62.0037 | O2: IBGE Localidades 2022 (Sede Municipal) | P2: OK | Q2: Não | R2: 6 | S2: 110001505 | T2: Alta Floresta D'Oeste | U2: Alta Floresta D'Oeste; Filadélfia d'Oeste; Izidolândia; Nova Gease d'Oeste; Rolim de Moura do Guaporé; Santo Antônio d'Oeste | V2: Sim | X2: -12.469748 | Y2: -62.274475 | Z2: Não | AA2: -12.119936 | AB2: -62.222413
A3: 1100023 | B3: 110002 | C3: Ariquemes | D3: Ariquemes - RO | E3: RO | F3: 11 | G3: Rondônia | H3: Norte | I3: 1101 | J3: Porto Velho | K3: 110002 | L3: Ariquemes | M3: -9.912 | N3: -63.0338 | O3: IBGE Localidades 2022 (Sede Municipal) | P3: OK | Q3: Não | R3: 1 | S3: 110002305 | T3: Ariquemes | U3: Ariquemes | V3: Sim | X3: -9.951978 | Y3: -62.957227 | Z3: Sim | AA3: -9.966212 | AB3: -62.911906
A4: 1100031 | B4: 110003 | C4: Cabixi | D4: Cabixi - RO | E4: RO | F4: 11 | G4: Rondônia | H4: Norte | I4: 1102 | J4: Ji-Paraná | K4: 110006 | L4: Vilhena | M4: -13.4945 | N4: -60.5429 | O4: IBGE Localidades 2022 (Sede Municipal) | P4: OK | Q4: Não | R4: 1 | S4: 110003105 | T4: Cabixi | U4: Cabixi | V4: Sim | X4: -13.474933 | Y4: -60.639811 | Z4: Sim | AA4: -13.436056 | AB4: -60.611615
A5: 1100049 | B5: 110004 | C5: Cacoal | D5: Cacoal - RO | E5: RO | F5: 11 | G5: Rondônia | H5: Norte | I5: 1102 | J5: Ji-Paraná | K5: 110005 | L5: Cacoal | M5: -11.4356 | N5: -61.4512 | O5: IBGE Localidades 2022 (Sede Municipal) | P5: OK | Q5: Não | R5: 3 | S5: 110004905 | T5: Cacoal | U5: Cacoal; Riozinho; Divinópolis | V5: Sim | X5: -11.301275 | Y5: -61.324642 | Z5: Sim | AA5: -11.261263 | AB5: -61.240318
A6: 1100056 | B6: 110005 | C6: Cerejeiras | D6: Cerejeiras - RO | E6: RO | F6: 11 | G6: Rondônia | H6: Norte | I6: 1102 | J6: Ji-Paraná | K6: 110006 | L6: Vilhena | M6: -13.1864 | N6: -60.8117 | O6: IBGE Localidades 2022 (Sede Municipal) | P6: OK | Q6: Não | R6: 1 | S6: 110005605 | T6: Cerejeiras | U6: Cerejeiras | V6: Sim | X6: -13.203677 | Y6: -61.260923 | Z6: Sim | AA6: -13.232552 | AB6: -61.226979
A7: 1100064 | B7: 110006 | C7: Colorado do Oeste | D7: Colorado do Oeste - RO | E7: RO | F7: 11 | G7: Rondônia | H7: Norte | I7: 1102 | J7: Ji-Paraná | K7: 110006 | L7: Vilhena | M7: -13.1212 | N7: -60.5437 | O7: IBGE Localidades 2022 (Sede Municipal) | P7: OK | Q7: Não | R7: 1 | S7: 110006405 | T7: Colorado do Oeste | U7: Colorado do Oeste | V7: Sim | X7: -13.159152 | Y7: -60.550244 | Z7: Sim | AA7: -13.155651 | AB7: -60.556034
A8: 1100072 | B8: 110007 | C8: Corumbiara | D8: Corumbiara - RO | E8: RO | F8: 11 | G8: Rondônia | H8: Norte | I8: 1102 | J8: Ji-Paraná | K8: 110006 | L8: Vilhena | M8: -12.99752 | N8: -60.948701 | O8: IBGE Localidades 2010 (Cidade) | P8: Corrigida | Q8: Não | R8: 1 | S8: 110007205 | T8: Corumbiara | U8: Corumbiara | V8: Sim | W8: Ponto IBGE 2022 (-13,0092; -61,1279) divergia 19,5 km do IBGE 2010 e 26,0 km da base independente; substituído pelo IBGE 2010. O ponto 2022 coincide com Povoado 'Vitória da União' (IBGE 2010, a 0,29 km). IBGE 2010 x base independente: 7,5 km. A base independente aponta para o Povoado Alto Guarajus; o ponto IBGE 2010 é a área urbana (CIDADE) da sede. | X8: -12.92671 | Y8: -61.091629 | Z8: Sim | AA8: -12.942427 | AB8: -61.138893
A9: 1100080 | B9: 110008 | C9: Costa Marques | D9: Costa Marques - RO | E9: RO | F9: 11 | G9: Rondônia | H9: Norte | I9: 1102 | J9: Ji-Paraná | K9: 110004 | L9: Ji-Paraná | M9: -12.4384 | N9: -64.2292 | O9: IBGE Localidades 2022 (Sede Municipal) | P9: OK | Q9: Não | R9: 3 | S9: 110008005 | T9: Costa Marques | U9: Costa Marques; Real Forte Príncipe da Beira; São Domingos do Guaporé | V9: Sim | X9: -12.147029 | Y9: -64.05865 | Z9: Sim | AA9: -12.264719 | AB9: -64.266169
A10: 1100098 | B10: 110009 | C10: Espigão D'Oeste | D10: Espigão D'Oeste - RO | E10: RO | F10: 11 | G10: Rondônia | H10: Norte | I10: 1102 | J10: Ji-Paraná | K10: 110005 | L10: Cacoal | M10: -11.5347 | N10: -61.0164 | O10: IBGE Localidades 2022 (Sede Municipal) | P10: OK | Q10: Não | R10: 5 | S10: 110009805 | T10: Espigão D'Oeste | U10: Espigão D'Oeste; Boa Vista do Pacarana; Novo Paraíso; Flor da Serra; Nova Esperança | V10: Sim | X10: -11.35125 | Y10: -60.784792 | Z10: Sim | AA10: -11.380248 | AB10: -60.747569
A11: 1100106 | B11: 110010 | C11: Guajará-Mirim | D11: Guajará-Mirim - RO | E11: RO | F11: 11 | G11: Rondônia | H11: Norte | I11: 1101 | J11: Porto Velho | K11: 110001 | L11: Porto Velho | M11: -10.7871 | N11: -65.3401 | O11: IBGE Localidades 2022 (Sede Municipal) | P11: OK | Q11: Não | R11: 3 | S11: 110010605 | T11: Guajará-Mirim | U11: Guajará-Mirim; Iata; Surpresa | V11: Sim | X11: -11.305446 | Y11: -64.537754 | Z11: Sim | AA11: -11.4145 | AB11: -64.568417
A12: 1100114 | B12: 110011 | C12: Jaru | D12: Jaru - RO | E12: RO | F12: 11 | G12: Rondônia | H12: Norte | I12: 1101 | J12: Porto Velho | K12: 110003 | L12: Jaru | M12: -10.4382 | N12: -62.4616 | O12: IBGE Localidades 2022 (Sede Municipal) | P12: OK | Q12: Não | R12: 4 | S12: 110011405 | T12: Jaru | U12: Jaru; Bom Jesus; Santa Cruz da Serra; Tarilândia | V12: Sim | X12: -10.592342 | Y12: -62.58456 | Z12: Sim | AA12: -10.447166 | AB12: -62.436084
A13: 1100122 | B13: 110012 | C13: Ji-Paraná | D13: Ji-Paraná - RO | E13: RO | F13: 11 | G13: Rondônia | H13: Norte | I13: 1102 | J13: Ji-Paraná | K13: 110004 | L13: Ji-Paraná | M13: -10.8768 | N13: -61.9575 | O13: IBGE Localidades 2022 (Sede Municipal) | P13: OK | Q13: Não | R13: 3 | S13: 110012205 | T13: Ji-Paraná | U13: Ji-Paraná; Nova Colina; Nova Londrina | V13: Sim | X13: -10.461772 | Y13: -61.757131 | Z13: Sim | AA13: -10.726052 | AB13: -61.766934
A14: 1100130 | B14: 110013 | C14: Machadinho D'Oeste | D14: Machadinho D'Oeste - RO | E14: RO | F14: 11 | G14: Rondônia | H14: Norte | I14: 1101 | J14: Porto Velho | K14: 110003 | L14: Jaru | M14: -9.425562 | N14: -61.999593 | O14: IBGE Localidades 2010 (Cidade) | P14: Corrigida | Q14: Não | R14: 4 | S14: 110013005 | T14: Machadinho D'Oeste | U14: Machadinho D'Oeste; Oriente Novo; Quinto BEC; Tabajara | V14: Sim | W14: Ponto IBGE 2022 (-9,4657; -62,2562) divergia 28,5 km do IBGE 2010 e 30,2 km da base independente; substituído pelo IBGE 2010. O ponto 2022 está isolado (localidade IBGE 2010 mais próxima a 20,5 km). | X14: -9.203934 | Y14: -62.010232 | Z14: Sim | AA14: -9.205744 | AB14: -61.98143
A15: 1100148 | B15: 110014 | C15: Nova Brasilândia D'Oeste | D15: Nova Brasilândia D'Oeste - RO | E15: RO | F15: 11 | G15: Rondônia | H15: Norte | I15: 1102 | J15: Ji-Paraná | K15: 110005 | L15: Cacoal | M15: -11.7198 | N15: -62.3177 | O15: IBGE Localidades 2022 (Sede Municipal) | P15: OK | Q15: Não | R15: 1 | S15: 110014805 | T15: Nova Brasilândia D'Oeste | U15: Nova Brasilândia D'Oeste | V15: Sim | X15: -11.643028 | Y15: -62.280126 | Z15: Sim | AA15: -11.761104 | AB15: -62.342469
A16: 1100155 | B16: 110015 | C16: Ouro Preto do Oeste | D16: Ouro Preto do Oeste - RO | E16: RO | F16: 11 | G16: Rondônia | H16: Norte | I16: 1102 | J16: Ji-Paraná | K16: 110004 | L16: Ji-Paraná | M16: -10.7192 | N16: -62.2555 | O16: IBGE Localidades 2022 (Sede Municipal) | P16: OK | Q16: Não | R16: 2 | S16: 110015505 | T16: Ouro Preto do Oeste | U16: Ouro Preto do Oeste; Rondominas | V16: Sim | X16: -10.610499 | Y16: -62.172411 | Z16: Não | AA16: -10.708894 | AB16: -62.328823
A17: 1100189 | B17: 110018 | C17: Pimenta Bueno | D17: Pimenta Bueno - RO | E17: RO | F17: 11 | G17: Rondônia | H17: Norte | I17: 1102 | J17: Ji-Paraná | K17: 110005 | L17: Cacoal | M17: -11.6707 | N17: -61.1888 | O17: IBGE Localidades 2022 (Sede Municipal) | P17: OK | Q17: Não | R17: 3 | S17: 110018905 | T17: Pimenta Bueno | U17: Pimenta Bueno; Marco Rondon; Itaporanga | V17: Sim | X17: -11.894501 | Y17: -60.830539 | Z17: Sim | AA17: -11.93472 | AB17: -60.651141
A18: 1100205 | B18: 110020 | C18: Porto Velho | D18: Porto Velho - RO | E18: RO | F18: 11 | G18: Rondônia | H18: Norte | I18: 1101 | J18: Porto Velho | K18: 110001 | L18: Porto Velho | M18: -8.768892 | N18: -63.831446 | O18: IBGE Localidades 2010 (Cidade) | P18: Corrigida - a conferir | Q18: Sim | R18: 12 | S18: 110020505 | T18: Porto Velho | U18: Porto Velho; Abunã; Calama; Demarcação; Extrema; Fortaleza do Abunã; Jaci Paraná; Mutum Paraná; Nazaré; Nova Califórnia; São Carlos; Vista Alegre do Abunã | V18: Sim | W18: Ponto IBGE 2022 (-9,6462; -63,9599) divergia 98,6 km do IBGE 2010 e 98,7 km da base independente; substituído pelo IBGE 2010. O ponto 2022 está isolado (localidade IBGE 2010 mais próxima a 63,5 km). IBGE 2010 x base independente: 7,6 km. O ponto IBGE 2010 fica na Zona Leste da cidade; para análises que exijam o centro, use a coordenada publicada pela Prefeitura. Referência externa — Prefeitura de Porto Velho (8°45'43"S 63°54'14"W, centro): (-8,7619; -63,9039), a 8,0 km do ponto adotado. | X18: -9.154117 | Y18: -64.304271 | Z18: Sim | AA18: -9.445094 | AB18: -64.53976
A19: 1100254 | B19: 110025 | C19: Presidente Médici | D19: Presidente Médici - RO | E19: RO | F19: 11 | G19: Rondônia | H19: Norte | I19: 1102 | J19: Ji-Paraná | K19: 110004 | L19: Ji-Paraná | M19: -11.1698 | N19: -61.9041 | O19: IBGE Localidades 2022 (Sede Municipal) | P19: OK | Q19: Não | R19: 5 | S19: 110025405 | T19: Presidente Médici | U19: Presidente Médici; Estrela de Rondônia; Novo Riachuelo; Vila Bandeira Branca; Vila Camargo | V19: Sim | X19: -11.166306 | Y19: -61.877867 | Z19: Sim | AA19: -11.171763 | AB19: -61.822196
A20: 1100262 | B20: 110026 | C20: Rio Crespo | D20: Rio Crespo - RO | E20: RO | F20: 11 | G20: Rondônia | H20: Norte | I20: 1101 | J20: Porto Velho | K20: 110002 | L20: Ariquemes | M20: -9.7054 | N20: -62.8983 | O20: IBGE Localidades 2022 (Sede Municipal) | P20: OK | Q20: Não | R20: 1 | S20: 110026205 | T20: Rio Crespo | U20: Rio Crespo | V20: Sim | X20: -9.645216 | Y20: -62.790059 | Z20: Sim | AA20: -9.663163 | AB20: -62.729992
A21: 1100288 | B21: 110028 | C21: Rolim de Moura | D21: Rolim de Moura - RO | E21: RO | F21: 11 | G21: Rondônia | H21: Norte | I21: 1102 | J21: Ji-Paraná | K21: 110005 | L21: Cacoal | M21: -11.722259 | N21: -61.785781 | O21: IBGE Localidades 2010 (Cidade) | P21: Corrigida | Q21: Não | R21: 2 | S21: 110028805 | T21: Rolim de Moura | U21: Rolim de Moura; Nova Estrela | V21: Sim | W21: Ponto IBGE 2022 (-11,7251; -61,5543) divergia 25,2 km do IBGE 2010 e 23,6 km da base independente; substituído pelo IBGE 2010. O ponto 2022 coincide com Povoado 'Nova Estrela' (IBGE 2010, a 0,80 km). | X21: -11.732597 | Y21: -61.771654 | Z21: Sim | AA21: -11.720485 | AB21: -61.707357
A22: 1100296 | B22: 110029 | C22: Santa Luzia D'Oeste | D22: Santa Luzia D'Oeste - RO | E22: RO | F22: 11 | G22: Rondônia | H22: Norte | I22: 1102 | J22: Ji-Paraná | K22: 110005 | L22: Cacoal | M22: -11.9079 | N22: -61.7846 | O22: IBGE Localidades 2022 (Sede Municipal) | P22: OK | Q22: Não | R22: 1 | S22: 110029605 | T22: Santa Luzia D'Oeste | U22: Santa Luzia D'Oeste | V22: Sim | X22: -12.026896 | Y22: -61.701119 | Z22: Sim | AA22: -11.97654 | AB22: -61.718828
A23: 1100304 | B23: 110030 | C23: Vilhena | D23: Vilhena - RO | E23: RO | F23: 11 | G23: Rondônia | H23: Norte | I23: 1102 | J23: Ji-Paraná | K23: 110006 | L23: Vilhena | M23: -12.7351 | N23: -60.1348 | O23: IBGE Localidades 2022 (Sede Municipal) | P23: OK | Q23: Não | R23: 1 | S23: 110030405 | T23: Vilhena | U23: Vilhena | V23: Sim | X23: -12.094901 | Y23: -60.248545 | Z23: Sim | AA23: -12.476569 | AB23: -60.218252
A24: 1100320 | B24: 110032 | C24: São Miguel do Guaporé | D24: São Miguel do Guaporé - RO | E24: RO | F24: 11 | G24: Rondônia | H24: Norte | I24: 1102 | J24: Ji-Paraná | K24: 110004 | L24: Ji-Paraná | M24: -11.689 | N24: -62.7152 | O24: IBGE Localidades 2022 (Sede Municipal) | P24: OK | Q24: Não | R24: 2 | S24: 110032005 | T24: São Miguel do Guaporé | U24: São Miguel do Guaporé; Santana do Guaporé | V24: Sim | X24: -11.612069 | Y24: -62.98815 | Z24: Não | AA24: -11.328409 | AB24: -63.33839
A25: 1100338 | B25: 110033 | C25: Nova Mamoré | D25: Nova Mamoré - RO | E25: RO | F25: 11 | G25: Rondônia | H25: Norte | I25: 1101 | J25: Porto Velho | K25: 110001 | L25: Porto Velho | M25: -10.4174 | N25: -65.3321 | O25: IBGE Localidades 2022 (Sede Municipal) | P25: OK | Q25: Não | R25: 6 | S25: 110033805 | T25: Nova Mamoré | U25: Nova Mamoré; Araras; Jacynópolis; Nova Dimensão; Palmeiras; Nova Marechal Rondon | V25: Sim | X25: -10.382233 | Y25: -64.629367 | Z25: Sim | AA25: -10.284917 | AB25: -64.512351
A26: 1100346 | B26: 110034 | C26: Alvorada D'Oeste | D26: Alvorada D'Oeste - RO | E26: RO | F26: 11 | G26: Rondônia | H26: Norte | I26: 1102 | J26: Ji-Paraná | K26: 110004 | L26: Ji-Paraná | M26: -11.3547 | N26: -62.2845 | O26: IBGE Localidades 2022 (Sede Municipal) | P26: OK | Q26: Não | R26: 3 | S26: 110034605 | T26: Alvorada D'Oeste | U26: Alvorada D'Oeste; Tancredópolis; Terra Boa | V26: Sim | X26: -11.311477 | Y26: -62.545137 | Z26: Sim | AA26: -11.345299 | AB26: -62.42378
A27: 1100379 | B27: 110037 | C27: Alto Alegre dos Parecis | D27: Alto Alegre dos Parecis - RO | E27: RO | F27: 11 | G27: Rondônia | H27: Norte | I27: 1102 | J27: Ji-Paraná | K27: 110005 | L27: Cacoal | M27: -12.134 | N27: -61.8587 | O27: IBGE Localidades 2022 (Sede Municipal) | P27: OK | Q27: Não | R27: 1 | S27: 110037905 | T27: Alto Alegre dos Parecis | U27: Alto Alegre dos Parecis | V27: Sim | X27: -12.593422 | Y27: -61.880598 | Z27: Sim | AA27: -12.584885 | AB27: -61.798945
A28: 1100403 | B28: 110040 | C28: Alto Paraíso | D28: Alto Paraíso - RO | E28: RO | F28: 11 | G28: Rondônia | H28: Norte | I28: 1101 | J28: Porto Velho | K28: 110002 | L28: Ariquemes | M28: -9.7201 | N28: -63.3179 | O28: IBGE Localidades 2022 (Sede Municipal) | P28: OK | Q28: Não | R28: 1 | S28: 110040305 | T28: Alto Paraíso | U28: Alto Paraíso | V28: Sim | X28: -9.649294 | Y28: -63.394227 | Z28: Sim | AA28: -9.613147 | AB28: -63.346634
A29: 1100452 | B29: 110045 | C29: Buritis | D29: Buritis - RO | E29: RO | F29: 11 | G29: Rondônia | H29: Norte | I29: 1101 | J29: Porto Velho | K29: 110002 | L29: Ariquemes | M29: -10.2025 | N29: -63.8349 | O29: IBGE Localidades 2022 (Sede Municipal) | P29: OK | Q29: Não | R29: 1 | S29: 110045205 | T29: Buritis | U29: Buritis | V29: Sim | X29: -10.052139 | Y29: -63.94119 | Z29: Sim | AA29: -10.005082 | AB29: -63.9394
A30: 1100502 | B30: 110050 | C30: Novo Horizonte do Oeste | D30: Novo Horizonte do Oeste - RO | E30: RO | F30: 11 | G30: Rondônia | H30: Norte | I30: 1102 | J30: Ji-Paraná | K30: 110005 | L30: Cacoal | M30: -11.7065 | N30: -62.0001 | O30: IBGE Localidades 2022 (Sede Municipal) | P30: OK | Q30: Não | R30: 2 | S30: 110050205 | T30: Novo Horizonte do Oeste | U30: Novo Horizonte do Oeste; Migrantinópolis | V30: Sim | X30: -11.680995 | Y30: -62.083184 | Z30: Sim | AA30: -11.70893 | AB30: -62.088049
A31: 1100601 | B31: 110060 | C31: Cacaulândia | D31: Cacaulândia - RO | E31: RO | F31: 11 | G31: Rondônia | H31: Norte | I31: 1101 | J31: Porto Velho | K31: 110002 | L31: Ariquemes | M31: -10.3423 | N31: -62.9011 | O31: IBGE Localidades 2022 (Sede Municipal) | P31: OK | Q31: Não | R31: 1 | S31: 110060105 | T31: Cacaulândia | U31: Cacaulândia | V31: Sim | X31: -10.331607 | Y31: -62.987203 | Z31: Sim | AA31: -10.329488 | AB31: -63.072489
A32: 1100700 | B32: 110070 | C32: Campo Novo de Rondônia | D32: Campo Novo de Rondônia - RO | E32: RO | F32: 11 | G32: Rondônia | H32: Norte | I32: 1101 | J32: Porto Velho | K32: 110002 | L32: Ariquemes | M32: -10.568 | N32: -63.6201 | O32: IBGE Localidades 2022 (Sede Municipal) | P32: OK | Q32: Não | R32: 1 | S32: 110070005 | T32: Campo Novo de Rondônia | U32: Campo Novo de Rondônia | V32: Sim | X32: -10.484943 | Y32: -63.799717 | Z32: Sim | AA32: -10.538987 | AB32: -63.757288
A33: 1100809 | B33: 110080 | C33: Candeias do Jamari | D33: Candeias do Jamari - RO | E33: RO | F33: 11 | G33: Rondônia | H33: Norte | I33: 1101 | J33: Porto Velho | K33: 110001 | L33: Porto Velho | M33: -8.7966 | N33: -63.7006 | O33: IBGE Localidades 2022 (Sede Municipal) | P33: OK | Q33: Não | R33: 2 | S33: 110080905 | T33: Candeias do Jamari | U33: Candeias do Jamari; Rio Preto do Candeias | V33: Sim | X33: -8.886971 | Y33: -63.325398 | Z33: Sim | AA33: -8.738736 | AB33: -63.085037
A34: 1100908 | B34: 110090 | C34: Castanheiras | D34: Castanheiras - RO | E34: RO | F34: 11 | G34: Rondônia | H34: Norte | I34: 1102 | J34: Ji-Paraná | K34: 110005 | L34: Cacoal | M34: -11.426842 | N34: -61.949161 | O34: IBGE Localidades 2010 (Cidade) | P34: Corrigida | Q34: Não | R34: 1 | S34: 110090805 | T34: Castanheiras | U34: Castanheiras | V34: Sim | W34: Ponto IBGE 2022 (-11,5005; -61,8876) divergia 10,6 km do IBGE 2010 e 10,7 km da base independente; substituído pelo IBGE 2010. O ponto 2022 coincide com Povoado 'Jardinópolis' (IBGE 2010, a 0,55 km). | X34: -11.470791 | Y34: -61.880139 | Z34: Sim | AA34: -11.476983 | AB34: -61.892774
A35: 1100924 | B35: 110092 | C35: Chupinguaia | D35: Chupinguaia - RO | E35: RO | F35: 11 | G35: Rondônia | H35: Norte | I35: 1102 | J35: Ji-Paraná | K35: 110006 | L35: Vilhena | M35: -12.5514 | N35: -60.8997 | O35: IBGE Localidades 2022 (Sede Municipal) | P35: OK | Q35: Não | R35: 1 | S35: 110092405 | T35: Chupinguaia | U35: Chupinguaia | V35: Sim | X35: -12.537216 | Y35: -60.899259 | Z35: Sim | AA35: -12.490685 | AB35: -61.027419
A36: 1100940 | B36: 110094 | C36: Cujubim | D36: Cujubim - RO | E36: RO | F36: 11 | G36: Rondônia | H36: Norte | I36: 1101 | J36: Porto Velho | K36: 110002 | L36: Ariquemes | M36: -9.3683 | N36: -62.5825 | O36: IBGE Localidades 2022 (Sede Municipal) | P36: OK | Q36: Não | R36: 1 | S36: 110094005 | T36: Cujubim | U36: Cujubim | V36: Sim | X36: -9.170907 | Y36: -62.565257 | Z36: Sim | AA36: -9.17565 | AB36: -62.53364
A37: 1101005 | B37: 110100 | C37: Governador Jorge Teixeira | D37: Governador Jorge Teixeira - RO | E37: RO | F37: 11 | G37: Rondônia | H37: Norte | I37: 1101 | J37: Porto Velho | K37: 110003 | L37: Jaru | M37: -10.6136 | N37: -62.7341 | O37: IBGE Localidades 2022 (Sede Municipal) | P37: OK | Q37: Não | R37: 2 | S37: 110100505 | T37: Governador Jorge Teixeira | U37: Governador Jorge Teixeira; Colina Verde | V37: Sim | X37: -10.748038 | Y37: -63.183977 | Z37: Sim | AA37: -10.765933 | AB37: -63.276479
A38: 1101104 | B38: 110110 | C38: Itapuã do Oeste | D38: Itapuã do Oeste - RO | E38: RO | F38: 11 | G38: Rondônia | H38: Norte | I38: 1101 | J38: Porto Velho | K38: 110001 | L38: Porto Velho | M38: -9.1871 | N38: -63.1884 | O38: IBGE Localidades 2022 (Sede Municipal) | P38: OK | Q38: Não | R38: 1 | S38: 110110405 | T38: Itapuã do Oeste | U38: Itapuã do Oeste | V38: Sim | X38: -9.170292 | Y38: -63.044923 | Z38: Sim | AA38: -9.230147 | AB38: -63.043504
A39: 1101203 | B39: 110120 | C39: Ministro Andreazza | D39: Ministro Andreazza - RO | E39: RO | F39: 11 | G39: Rondônia | H39: Norte | I39: 1102 | J39: Ji-Paraná | K39: 110005 | L39: Cacoal | M39: -11.1969 | N39: -61.5177 | O39: IBGE Localidades 2022 (Sede Municipal) | P39: OK | Q39: Não | R39: 1 | S39: 110120305 | T39: Ministro Andreazza | U39: Ministro Andreazza | V39: Sim | X39: -11.160218 | Y39: -61.56891 | Z39: Sim | AA39: -11.183936 | AB39: -61.583733
A40: 1101302 | B40: 110130 | C40: Mirante da Serra | D40: Mirante da Serra - RO | E40: RO | F40: 11 | G40: Rondônia | H40: Norte | I40: 1102 | J40: Ji-Paraná | K40: 110004 | L40: Ji-Paraná | M40: -11.0308 | N40: -62.6746 | O40: IBGE Localidades 2022 (Sede Municipal) | P40: OK | Q40: Não | R40: 1 | S40: 110130205 | T40: Mirante da Serra | U40: Mirante da Serra | V40: Sim | X40: -11.076826 | Y40: -62.84783 | Z40: Sim | AA40: -11.048959 | AB40: -62.760346
...

Sheet Distritos
A1: Código Distrito | B1: Distrito | C1: Distrito-Sede | D1: Código IBGE | E1: Município | F1: Município - UF | G1: UF | H1: Código UF | I1: Estado | J1: Região | K1: Código Região Intermediária | L1: Região Geográfica Intermediária | M1: Código Região Imediata | N1: Região Geográfica Imediata | O1: Latitude Município | P1: Longitude Município | Q1: Latitude Distrito | R1: Longitude Distrito | S1: Fonte Coordenada Distrito | T1: Observação
A2: 110001505 | B2: Alta Floresta D'Oeste | C2: Sim | D2: 1100015 | E2: Alta Floresta D'Oeste | F2: Alta Floresta D'Oeste - RO | G2: RO | H2: 11 | I2: Rondônia | J2: Norte | K2: 1102 | L2: Ji-Paraná | M2: 110005 | N2: Cacoal | O2: -11.933 | P2: -62.0037 | Q2: -11.933 | R2: -62.0037 | S2: IBGE Localidades 2022 (Sede Municipal) — sede municipal
A3: 110001515 | B3: Filadélfia d'Oeste | C3: Não | D3: 1100015 | E3: Alta Floresta D'Oeste | F3: Alta Floresta D'Oeste - RO | G3: RO | H3: 11 | I3: Rondônia | J3: Norte | K3: 1102 | L3: Ji-Paraná | M3: 110005 | N3: Cacoal | O3: -11.933 | P3: -62.0037 | Q3: -12.437239 | R3: -62.043898 | S3: IBGE Localidades 2010 (Vila)
A4: 110001520 | B4: Izidolândia | C4: Não | D4: 1100015 | E4: Alta Floresta D'Oeste | F4: Alta Floresta D'Oeste - RO | G4: RO | H4: 11 | I4: Rondônia | J4: Norte | K4: 1102 | L4: Ji-Paraná | M4: 110005 | N4: Cacoal | O4: -11.933 | P4: -62.0037 | Q4: -12.601415 | R4: -62.175549 | S4: IBGE Localidades 2010 (Vila)
A5: 110001525 | B5: Nova Gease d'Oeste | C5: Não | D5: 1100015 | E5: Alta Floresta D'Oeste | F5: Alta Floresta D'Oeste - RO | G5: RO | H5: 11 | I5: Rondônia | J5: Norte | K5: 1102 | L5: Ji-Paraná | M5: 110005 | N5: Cacoal | O5: -11.933 | P5: -62.0037 | Q5: -11.919792 | R5: -62.31865 | S5: IBGE Localidades 2010 (Vila)
A6: 110001530 | B6: Rolim de Moura do Guaporé | C6: Não | D6: 1100015 | E6: Alta Floresta D'Oeste | F6: Alta Floresta D'Oeste - RO | G6: RO | H6: 11 | I6: Rondônia | J6: Norte | K6: 1102 | L6: Ji-Paraná | M6: 110005 | N6: Cacoal | O6: -11.933 | P6: -62.0037 | Q6: -13.079806 | R6: -62.276812 | S6: IBGE Localidades 2010 (Vila)
A7: 110001535 | B7: Santo Antônio d'Oeste | C7: Não | D7: 1100015 | E7: Alta Floresta D'Oeste | F7: Alta Floresta D'Oeste - RO | G7: RO | H7: 11 | I7: Rondônia | J7: Norte | K7: 1102 | L7: Ji-Paraná | M7: 110005 | N7: Cacoal | O7: -11.933 | P7: -62.0037 | Q7: -12.089439 | R7: -62.104428 | S7: IBGE Localidades 2010 (Vila)
A8: 110002305 | B8: Ariquemes | C8: Sim | D8: 1100023 | E8: Ariquemes | F8: Ariquemes - RO | G8: RO | H8: 11 | I8: Rondônia | J8: Norte | K8: 1101 | L8: Porto Velho | M8: 110002 | N8: Ariquemes | O8: -9.912 | P8: -63.0338 | Q8: -9.912 | R8: -63.0338 | S8: IBGE Localidades 2022 (Sede Municipal) — sede municipal
A9: 110003105 | B9: Cabixi | C9: Sim | D9: 1100031 | E9: Cabixi | F9: Cabixi - RO | G9: RO | H9: 11 | I9: Rondônia | J9: Norte | K9: 1102 | L9: Ji-Paraná | M9: 110006 | N9: Vilhena | O9: -13.4945 | P9: -60.5429 | Q9: -13.4945 | R9: -60.5429 | S9: IBGE Localidades 2022 (Sede Municipal) — sede municipal
A10: 110004905 | B10: Cacoal | C10: Sim | D10: 1100049 | E10: Cacoal | F10: Cacoal - RO | G10: RO | H10: 11 | I10: Rondônia | J10: Norte | K10: 1102 | L10: Ji-Paraná | M10: 110005 | N10: Cacoal | O10: -11.4356 | P10: -61.4512 | Q10: -11.4356 | R10: -61.4512 | S10: IBGE Localidades 2022 (Sede Municipal) — sede municipal
A11: 110004910 | B11: Riozinho | C11: Não | D11: 1100049 | E11: Cacoal | F11: Cacoal - RO | G11: RO | H11: 11 | I11: Rondônia | J11: Norte | K11: 1102 | L11: Ji-Paraná | M11: 110005 | N11: Cacoal | O11: -11.4356 | P11: -61.4512 | Q11: -11.51061 | R11: -61.359715 | S11: IBGE Localidades 2010 (Vila)
A12: 110004915 | B12: Divinópolis | C12: Não | D12: 1100049 | E12: Cacoal | F12: Cacoal - RO | G12: RO | H12: 11 | I12: Rondônia | J12: Norte | K12: 1102 | L12: Ji-Paraná | M12: 110005 | N12: Cacoal | O12: -11.4356 | P12: -61.4512 | S12: Sem ponto oficial de sede distrital | T12: Distrito criado após 2010 (sem ponto IBGE 2022 nos arquivos disponíveis, que cobrem só GO, SC, AM, AP, PA e RR).
A13: 110005605 | B13: Cerejeiras | C13: Sim | D13: 1100056 | E13: Cerejeiras | F13: Cerejeiras - RO | G13: RO | H13: 11 | I13: Rondônia | J13: Norte | K13: 1102 | L13: Ji-Paraná | M13: 110006 | N13: Vilhena | O13: -13.1864 | P13: -60.8117 | Q13: -13.1864 | R13: -60.8117 | S13: IBGE Localidades 2022 (Sede Municipal) — sede municipal
A14: 110006405 | B14: Colorado do Oeste | C14: Sim | D14: 1100064 | E14: Colorado do Oeste | F14: Colorado do Oeste - RO | G14: RO | H14: 11 | I14: Rondônia | J14: Norte | K14: 1102 | L14: Ji-Paraná | M14: 110006 | N14: Vilhena | O14: -13.1212 | P14: -60.5437 | Q14: -13.1212 | R14: -60.5437 | S14: IBGE Localidades 2022 (Sede Municipal) — sede municipal
A15: 110007205 | B15: Corumbiara | C15: Sim | D15: 1100072 | E15: Corumbiara | F15: Corumbiara - RO | G15: RO | H15: 11 | I15: Rondônia | J15: Norte | K15: 1102 | L15: Ji-Paraná | M15: 110006 | N15: Vilhena | O15: -12.99752 | P15: -60.948701 | Q15: -12.99752 | R15: -60.948701 | S15: IBGE Localidades 2010 (Cidade) — sede municipal
A16: 110008005 | B16: Costa Marques | C16: Sim | D16: 1100080 | E16: Costa Marques | F16: Costa Marques - RO | G16: RO | H16: 11 | I16: Rondônia | J16: Norte | K16: 1102 | L16: Ji-Paraná | M16: 110004 | N16: Ji-Paraná | O16: -12.4384 | P16: -64.2292 | Q16: -12.4384 | R16: -64.2292 | S16: IBGE Localidades 2022 (Sede Municipal) — sede municipal
A17: 110008015 | B17: Real Forte Príncipe da Beira | C17: Não | D17: 1100080 | E17: Costa Marques | F17: Costa Marques - RO | G17: RO | H17: 11 | I17: Rondônia | J17: Norte | K17: 1102 | L17: Ji-Paraná | M17: 110004 | N17: Ji-Paraná | O17: -12.4384 | P17: -64.2292 | Q17: -12.42668 | R17: -64.42086 | S17: IBGE Localidades 2010 (Vila) | T17: Grafia na fonte do ponto: Príncipe da Beira.
A18: 110008035 | B18: São Domingos do Guaporé | C18: Não | D18: 1100080 | E18: Costa Marques | F18: Costa Marques - RO | G18: RO | H18: 11 | I18: Rondônia | J18: Norte | K18: 1102 | L18: Ji-Paraná | M18: 110004 | N18: Ji-Paraná | O18: -12.4384 | P18: -64.2292 | S18: Sem ponto oficial de sede distrital | T18: Distrito criado após 2010 (sem ponto IBGE 2022 nos arquivos disponíveis, que cobrem só GO, SC, AM, AP, PA e RR).
A19: 110009805 | B19: Espigão D'Oeste | C19: Sim | D19: 1100098 | E19: Espigão D'Oeste | F19: Espigão D'Oeste - RO | G19: RO | H19: 11 | I19: Rondônia | J19: Norte | K19: 1102 | L19: Ji-Paraná | M19: 110005 | N19: Cacoal | O19: -11.5347 | P19: -61.0164 | Q19: -11.5347 | R19: -61.0164 | S19: IBGE Localidades 2022 (Sede Municipal) — sede municipal
A20: 110009810 | B20: Boa Vista do Pacarana | C20: Não | D20: 1100098 | E20: Espigão D'Oeste | F20: Espigão D'Oeste - RO | G20: RO | H20: 11 | I20: Rondônia | J20: Norte | K20: 1102 | L20: Ji-Paraná | M20: 110005 | N20: Cacoal | O20: -11.5347 | P20: -61.0164 | Q20: -11.003153 | R20: -60.846795 | S20: IBGE Localidades 2010 (Vila)
A21: 110009812 | B21: Novo Paraíso | C21: Não | D21: 1100098 | E21: Espigão D'Oeste | F21: Espigão D'Oeste - RO | G21: RO | H21: 11 | I21: Rondônia | J21: Norte | K21: 1102 | L21: Ji-Paraná | M21: 110005 | N21: Cacoal | O21: -11.5347 | P21: -61.0164 | Q21: -11.461613 | R21: -60.923816 | S21: IBGE Localidades 2010 (Vila)
A22: 110009815 | B22: Flor da Serra | C22: Não | D22: 1100098 | E22: Espigão D'Oeste | F22: Espigão D'Oeste - RO | G22: RO | H22: 11 | I22: Rondônia | J22: Norte | K22: 1102 | L22: Ji-Paraná | M22: 110005 | N22: Cacoal | O22: -11.5347 | P22: -61.0164 | Q22: -11.405385 | R22: -60.751286 | S22: IBGE Localidades 2010 (Vila)
A23: 110009818 | B23: Nova Esperança | C23: Não | D23: 1100098 | E23: Espigão D'Oeste | F23: Espigão D'Oeste - RO | G23: RO | H23: 11 | I23: Rondônia | J23: Norte | K23: 1102 | L23: Ji-Paraná | M23: 110005 | N23: Cacoal | O23: -11.5347 | P23: -61.0164 | Q23: -11.50379 | R23: -61.132056 | S23: IBGE Localidades 2010 (Vila)
A24: 110010605 | B24: Guajará-Mirim | C24: Sim | D24: 1100106 | E24: Guajará-Mirim | F24: Guajará-Mirim - RO | G24: RO | H24: 11 | I24: Rondônia | J24: Norte | K24: 1101 | L24: Porto Velho | M24: 110001 | N24: Porto Velho | O24: -10.7871 | P24: -65.3401 | Q24: -10.7871 | R24: -65.3401 | S24: IBGE Localidades 2022 (Sede Municipal) — sede municipal
A25: 110010612 | B25: Iata | C25: Não | D25: 1100106 | E25: Guajará-Mirim | F25: Guajará-Mirim - RO | G25: RO | H25: 11 | I25: Rondônia | J25: Norte | K25: 1101 | L25: Porto Velho | M25: 110001 | N25: Porto Velho | O25: -10.7871 | P25: -65.3401 | Q25: -10.589854 | R25: -65.382828 | S25: IBGE Localidades 2010 (Vila)
A26: 110010622 | B26: Surpresa | C26: Não | D26: 1100106 | E26: Guajará-Mirim | F26: Guajará-Mirim - RO | G26: RO | H26: 11 | I26: Rondônia | J26: Norte | K26: 1101 | L26: Porto Velho | M26: 110001 | N26: Porto Velho | O26: -10.7871 | P26: -65.3401 | Q26: -11.88231 | R26: -65.021521 | S26: IBGE Localidades 2010 (Vila)
A27: 110011405 | B27: Jaru | C27: Sim | D27: 1100114 | E27: Jaru | F27: Jaru - RO | G27: RO | H27: 11 | I27: Rondônia | J27: Norte | K27: 1101 | L27: Porto Velho | M27: 110003 | N27: Jaru | O27: -10.4382 | P27: -62.4616 | Q27: -10.4382 | R27: -62.4616 | S27: IBGE Localidades 2022 (Sede Municipal) — sede municipal
A28: 110011410 | B28: Bom Jesus | C28: Não | D28: 1100114 | E28: Jaru | F28: Jaru - RO | G28: RO | H28: 11 | I28: Rondônia | J28: Norte | K28: 1101 | L28: Porto Velho | M28: 110003 | N28: Jaru | O28: -10.4382 | P28: -62.4616 | Q28: -10.315466 | R28: -62.24075 | S28: IBGE Localidades 2010 (Vila)
A29: 110011420 | B29: Santa Cruz da Serra | C29: Não | D29: 1100114 | E29: Jaru | F29: Jaru - RO | G29: RO | H29: 11 | I29: Rondônia | J29: Norte | K29: 1101 | L29: Porto Velho | M29: 110003 | N29: Jaru | O29: -10.4382 | P29: -62.4616 | Q29: -10.651474 | R29: -62.587104 | S29: IBGE Localidades 2010 (Vila)
A30: 110011425 | B30: Tarilândia | C30: Não | D30: 1100114 | E30: Jaru | F30: Jaru - RO | G30: RO | H30: 11 | I30: Rondônia | J30: Norte | K30: 1101 | L30: Porto Velho | M30: 110003 | N30: Jaru | O30: -10.4382 | P30: -62.4616 | Q30: -10.856914 | R30: -62.801313 | S30: IBGE Localidades 2010 (Vila)
... A42: 110018915 | B42: Marco Rondon | C42: Não | D42: 1100189 | E42: Pimenta Bueno | F42: Pimenta Bueno - RO | G42: RO | H42: 11 | I42: Rondônia | J42: Norte | K42: 1102 | L42: Ji-Paraná | M42: 110005 | N42: Cacoal | O42: -11.6707 | P42: -61.1888 | Q42: -12.013427 | R42: -60.860058 | S42: IBGE Localidades 2010 (Vila)
A43: 110018920 | B43: Itaporanga | C43: Não | D43: 1100189 | E43: Pimenta Bueno | F43: Pimenta Bueno - RO | G43: RO | H43: 11 | I43: Rondônia | J43: Norte | K43: 1102 | L43: Ji-Paraná | M43: 110005 | N43: Cacoal | O43: -11.6707 | P43: -61.1888 | S43: Sem ponto oficial de sede distrital | T43: Distrito criado após 2010 (sem ponto IBGE 2022 nos arquivos disponíveis, que cobrem só GO, SC, AM, AP, PA e RR).
A44: 110020505 | B44: Porto Velho | C44: Sim | D44: 1100205 | E44: Porto Velho | F44: Porto Velho - RO | G44: RO | H44: 11 | I44: Rondônia | J44: Norte | K44: 1101 | L44: Porto Velho | M44: 110001 | N44: Porto Velho | O44: -8.768892 | P44: -63.831446 | Q44: -8.768892 | R44: -63.831446 | S44: IBGE Localidades 2010 (Cidade) — sede municipal — a conferir | T44: Sede municipal marcada 'a conferir' — ver a observação na aba Municipios.
A45: 110020510 | B45: Abunã | C45: Não | D45: 1100205 | E45: Porto Velho | F45: Porto Velho - RO | G45: RO | H45: 11 | I45: Rondônia | J45: Norte | K45: 1101 | L45: Porto Velho | M45: 110001 | N45: Porto Velho | O45: -8.768892 | P45: -63.831446 | Q45: -9.685618 | R45: -65.371506 | S45: IBGE Localidades 2010 (Vila)
A46: 110020515 | B46: Calama | C46: Não | D46: 1100205 | E46: Porto Velho | F46: Porto Velho - RO | G46: RO | H46: 11 | I46: Rondônia | J46: Norte | K46: 1101 | L46: Porto Velho | M46: 110001 | N46: Porto Velho | O46: -8.768892 | P46: -63.831446 | Q46: -8.025412 | R46: -62.871889 | S46: IBGE Localidades 2010 (Vila)
A47: 110020516 | B47: Demarcação | C47: Não | D47: 1100205 | E47: Porto Velho | F47: Porto Velho - RO | G47: RO | H47: 11 | I47: Rondônia | J47: Norte | K47: 1101 | L47: Porto Velho | M47: 110001 | N47: Porto Velho | O47: -8.768892 | P47: -63.831446 | Q47: -8.166927 | R47: -62.777883 | S47: IBGE Localidades 2010 (Vila)
A48: 110020517 | B48: Extrema | C48: Não | D48: 1100205 | E48: Porto Velho | F48: Porto Velho - RO | G48: RO | H48: 11 | I48: Rondônia | J48: Norte | K48: 1101 | L48: Porto Velho | M48: 110001 | N48: Porto Velho | O48: -8.768892 | P48: -63.831446 | Q48: -9.77417 | R48: -66.35955 | S48: IBGE Localidades 2010 (Vila)
A49: 110020518 | B49: Fortaleza do Abunã | C49: Não | D49: 1100205 | E49: Porto Velho | F49: Porto Velho - RO | G49: RO | H49: 11 | I49: Rondônia | J49: Norte | K49: 1101 | L49: Porto Velho | M49: 110001 | N49: Porto Velho | O49: -8.768892 | P49: -63.831446 | Q49: -9.773464 | R49: -65.52162 | S49: IBGE Localidades 2010 (Vila)
A50: 110020520 | B50: Jaci Paraná | C50: Não | D50: 1100205 | E50: Porto Velho | F50: Porto Velho - RO | G50: RO | H50: 11 | I50: Rondônia | J50: Norte | K50: 1101 | L50: Porto Velho | M50: 110001 | N50: Porto Velho | O50: -8.768892 | P50: -63.831446 | Q50: -9.252668 | R50: -64.395109 | S50: IBGE Localidades 2010 (Vila)
A51: 110020525 | B51: Mutum Paraná | C51: Não | D51: 1100205 | E51: Porto Velho | F51: Porto Velho - RO | G51: RO | H51: 11 | I51: Rondônia | J51: Norte | K51: 1101 | L51: Porto Velho | M51: 110001 | N51: Porto Velho | O51: -8.768892 | P51: -63.831446 | Q51: -9.618672 | R51: -64.942707 | S51: IBGE Localidades 2010 (Vila)
...

Sheet Regioes_Imediatas
A1: Código Região Imediata | B1: Região Geográfica Imediata | C1: Região Imediata - UF | D1: Código Região Intermediária | E1: Região Geográfica Intermediária | F1: UF | G1: Código UF | H1: Qtd. Municípios
A2: 110001 | B2: Porto Velho | C2: Porto Velho - RO | D2: 1101 | E2: Porto Velho | F2: RO | G2: 11 | H2: 5
A3: 110002 | B3: Ariquemes | C3: Ariquemes - RO | D3: 1101 | E3: Porto Velho | F3: RO | G3: 11 | H3: 8
A4: 110003 | B4: Jaru | C4: Jaru - RO | D4: 1101 | E4: Porto Velho | F4: RO | G4: 11 | H4: 5
A5: 110004 | B5: Ji-Paraná | C5: Ji-Paraná - RO | D5: 1102 | E5: Ji-Paraná | F5: RO | G5: 11 | H5: 13
A6: 110005 | B6: Cacoal | C6: Cacoal - RO | D6: 1102 | E6: Ji-Paraná | F6: RO | G6: 11 | H6: 14
A7: 110006 | B7: Vilhena | C7: Vilhena - RO | D7: 1102 | E7: Ji-Paraná | F7: RO | G7: 11 | H7: 7
A8: 120001 | B8: Rio Branco | C8: Rio Branco - AC | D8: 1201 | E8: Rio Branco | F8: AC | G8: 12 | H8: 7
A9: 120002 | B9: Brasiléia | C9: Brasiléia - AC | D9: 1201 | E9: Rio Branco | F9: AC | G9: 12 | H9: 4
A10: 120003 | B10: Sena Madureira | C10: Sena Madureira - AC | D10: 1201 | E10: Rio Branco | F10: AC | G10: 12 | H10: 3
A11: 120004 | B11: Cruzeiro do Sul | C11: Cruzeiro do Sul - AC | D11: 1202 | E11: Cruzeiro do Sul | F11: AC | G11: 12 | H11: 5
A12: 120005 | B12: Tarauacá | C12: Tarauacá - AC | D12: 1202 | E12: Cruzeiro do Sul | F12: AC | G12: 12 | H12: 3
A13: 130001 | B13: Manaus | C13: Manaus - AM | D13: 1301 | E13: Manaus | F13: AM | G13: 13 | H13: 10
... A511: 530001 | B511: Distrito Federal | C511: Distrito Federal - DF | D511: 5301 | E511: Distrito Federal | F511: DF | G511: 53 | H511: 1

Sheet Regioes_Intermediarias
A1: Código Região Intermediária | B1: Região Geográfica Intermediária | C1: UF | D1: Código UF | E1: Qtd. Regiões Imediatas | F1: Qtd. Municípios
A2: 1101 | B2: Porto Velho | C2: RO | D2: 11 | E2: 3 | F2: 18
A3: 1102 | B3: Ji-Paraná | C3: RO | D3: 11 | E3: 3 | F3: 34
A4: 1201 | B4: Rio Branco | C4: AC | D4: 12 | E4: 3 | F4: 14
A5: 1202 | B5: Cruzeiro do Sul | C5: AC | D5: 12 | E5: 2 | F5: 8
A6: 1301 | B6: Manaus | C6: AM | D6: 13 | E6: 4 | F6: 21
A7: 1302 | B7: Tefé | C7: AM | D7: 13 | E7: 3 | F7: 21
A8: 1303 | B8: Lábrea | C8: AM | D8: 13 | E8: 2 | F8: 9
A9: 1304 | B9: Parintins | C9: AM | D9: 13 | E9: 2 | F9: 11
A10: 1401 | B10: Boa Vista | C10: RR | D10: 14 | E10: 2 | F10: 9
A11: 1402 | B11: Rorainópolis - Caracaraí | C11: RR | D11: 14 | E11: 2 | F11: 6
A12: 1501 | B12: Belém | C12: PA | D12: 15 | E12: 3 | F12: 23
A13: 1502 | B13: Castanhal | C13: PA | D13: 15 | E13: 5 | F13: 39
... A134: 5301 | B134: Distrito Federal | C134: DF | D134: 53 | E134: 1 | F134: 1

Sheet UFs
A1: Código UF | B1: UF | C1: Estado | D1: Código Região | E1: Região | F1: Município Capital
A2: 11 | B2: RO | C2: Rondônia | D2: 1 | E2: Norte | F2: Porto Velho
A3: 12 | B3: AC | C3: Acre | D3: 1 | E3: Norte | F3: Rio Branco
A4: 13 | B4: AM | C4: Amazonas | D4: 1 | E4: Norte | F4: Manaus
A5: 14 | B5: RR | C5: Roraima | D5: 1 | E5: Norte | F5: Boa Vista
A6: 15 | B6: PA | C6: Pará | D6: 1 | E6: Norte | F6: Belém
A7: 16 | B7: AP | C7: Amapá | D7: 1 | E7: Norte | F7: Macapá
A8: 17 | B8: TO | C8: Tocantins | D8: 1 | E8: Norte | F8: Palmas
A9: 21 | B9: MA | C9: Maranhão | D9: 2 | E9: Nordeste | F9: São Luís
A10: 22 | B10: PI | C10: Piauí | D10: 2 | E10: Nordeste | F10: Teresina
A11: 23 | B11: CE | C11: Ceará | D11: 2 | E11: Nordeste | F11: Fortaleza
A12: 24 | B12: RN | C12: Rio Grande do Norte | D12: 2 | E12: Nordeste | F12: Natal
A13: 25 | B13: PB | C13: Paraíba | D13: 2 | E13: Nordeste | F13: João Pessoa
... A28: 53 | B28: DF | C28: Distrito Federal | D28: 5 | E28: Centro-Oeste | F28: Brasília

Sheet Resumo_UF
A1: UF | B1: Estado | C1: Região | D1: Municípios | E1: Distritos | F1: Regiões Imediatas | G1: Regiões Intermediárias | H1: Coord. corrigidas (IBGE 2010) | I1: Média distritos/município
A2: RO | B2: Rondônia | C2: Norte | D2: =COUNTIF(Municipios!$E$2:$E$5572,$A2) -> 52 | E2: =COUNTIF(Distritos!$G$2:$G$10752,$A2) -> 108 | F2: =COUNTIF(Regioes_Imediatas!$F$2:$F$511,$A2) -> 6 | G2: =COUNTIF(Regioes_Intermediarias!$C$2:$C$134,$A2) -> 2 | H2: =COUNTIFS(Municipios!$E$2:$E$5572,$A2,Municipios!$O$2:$O$5572,"IBGE Localidades 2010*") -> 8 | I2: =IF(D2=0,0,E2/D2) -> 2.0769231
A3: AC | B3: Acre | C3: Norte | D3: =COUNTIF(Municipios!$E$2:$E$5572,$A3) -> 22 | E3: =COUNTIF(Distritos!$G$2:$G$10752,$A3) -> 26 | F3: =COUNTIF(Regioes_Imediatas!$F$2:$F$511,$A3) -> 5 | G3: =COUNTIF(Regioes_Intermediarias!$C$2:$C$134,$A3) -> 2 | H3: =COUNTIFS(Municipios!$E$2:$E$5572,$A3,Municipios!$O$2:$O$5572,"IBGE Localidades 2010*") -> 0 | I3: =IF(D3=0,0,E3/D3) -> 1.1818182
A4: AM | B4: Amazonas | C4: Norte | D4: =COUNTIF(Municipios!$E$2:$E$5572,$A4) -> 62 | E4: =COUNTIF(Distritos!$G$2:$G$10752,$A4) -> 103 | F4: =COUNTIF(Regioes_Imediatas!$F$2:$F$511,$A4) -> 11 | G4: =COUNTIF(Regioes_Intermediarias!$C$2:$C$134,$A4) -> 4 | H4: =COUNTIFS(Municipios!$E$2:$E$5572,$A4,Municipios!$O$2:$O$5572,"IBGE Localidades 2010*") -> 2 | I4: =IF(D4=0,0,E4/D4) -> 1.6612903
A5: RR | B5: Roraima | C5: Norte | D5: =COUNTIF(Municipios!$E$2:$E$5572,$A5) -> 15 | E5: =COUNTIF(Distritos!$G$2:$G$10752,$A5) -> 15 | F5: =COUNTIF(Regioes_Imediatas!$F$2:$F$511,$A5) -> 4 | G5: =COUNTIF(Regioes_Intermediarias!$C$2:$C$134,$A5) -> 2 | H5: =COUNTIFS(Municipios!$E$2:$E$5572,$A5,Municipios!$O$2:$O$5572,"IBGE Localidades 2010*") -> 0 | I5: =IF(D5=0,0,E5/D5) -> 1
A6: PA | B6: Pará | C6: Norte | D6: =COUNTIF(Municipios!$E$2:$E$5572,$A6) -> 144 | E6: =COUNTIF(Distritos!$G$2:$G$10752,$A6) -> 261 | F6: =COUNTIF(Regioes_Imediatas!$F$2:$F$511,$A6) -> 21 | G6: =COUNTIF(Regioes_Intermediarias!$C$2:$C$134,$A6) -> 7 | H6: =COUNTIFS(Municipios!$E$2:$E$5572,$A6,Municipios!$O$2:$O$5572,"IBGE Localidades 2010*") -> 0 | I6: =IF(D6=0,0,E6/D6) -> 1.8125
A7: AP | B7: Amapá | C7: Norte | D7: =COUNTIF(Municipios!$E$2:$E$5572,$A7) -> 16 | E7: =COUNTIF(Distritos!$G$2:$G$10752,$A7) -> 34 | F7: =COUNTIF(Regioes_Imediatas!$F$2:$F$511,$A7) -> 4 | G7: =COUNTIF(Regioes_Intermediarias!$C$2:$C$134,$A7) -> 2 | H7: =COUNTIFS(Municipios!$E$2:$E$5572,$A7,Municipios!$O$2:$O$5572,"IBGE Localidades 2010*") -> 0 | I7: =IF(D7=0,0,E7/D7) -> 2.125
A8: TO | B8: Tocantins | C8: Norte | D8: =COUNTIF(Municipios!$E$2:$E$5572,$A8) -> 139 | E8: =COUNTIF(Distritos!$G$2:$G$10752,$A8) -> 157 | F8: =COUNTIF(Regioes_Imediatas!$F$2:$F$511,$A8) -> 11 | G8: =COUNTIF(Regioes_Intermediarias!$C$2:$C$134,$A8) -> 3 | H8: =COUNTIFS(Municipios!$E$2:$E$5572,$A8,Municipios!$O$2:$O$5572,"IBGE Localidades 2010*") -> 0 | I8: =IF(D8=0,0,E8/D8) -> 1.1294964
A9: MA | B9: Maranhão | C9: Nordeste | D9: =COUNTIF(Municipios!$E$2:$E$5572,$A9) -> 217 | E9: =COUNTIF(Distritos!$G$2:$G$10752,$A9) -> 243 | F9: =COUNTIF(Regioes_Imediatas!$F$2:$F$511,$A9) -> 22 | G9: =COUNTIF(Regioes_Intermediarias!$C$2:$C$134,$A9) -> 5 | H9: =COUNTIFS(Municipios!$E$2:$E$5572,$A9,Municipios!$O$2:$O$5572,"IBGE Localidades 2010*") -> 1 | I9: =IF(D9=0,0,E9/D9) -> 1.1198157
A10: PI | B10: Piauí | C10: Nordeste | D10: =COUNTIF(Municipios!$E$2:$E$5572,$A10) -> 224 | E10: =COUNTIF(Distritos!$G$2:$G$10752,$A10) -> 224 | F10: =COUNTIF(Regioes_Imediatas!$F$2:$F$511,$A10) -> 19 | G10: =COUNTIF(Regioes_Intermediarias!$C$2:$C$134,$A10) -> 6 | H10: =COUNTIFS(Municipios!$E$2:$E$5572,$A10,Municipios!$O$2:$O$5572,"IBGE Localidades 2010*") -> 0 | I10: =IF(D10=0,0,E10/D10) -> 1
A11: CE | B11: Ceará | C11: Nordeste | D11: =COUNTIF(Municipios!$E$2:$E$5572,$A11) -> 184 | E11: =COUNTIF(Distritos!$G$2:$G$10752,$A11) -> 894 | F11: =COUNTIF(Regioes_Imediatas!$F$2:$F$511,$A11) -> 18 | G11: =COUNTIF(Regioes_Intermediarias!$C$2:$C$134,$A11) -> 6 | H11: =COUNTIFS(Municipios!$E$2:$E$5572,$A11,Municipios!$O$2:$O$5572,"IBGE Localidades 2010*") -> 0 | I11: =IF(D11=0,0,E11/D11) -> 4.8586957
A12: RN | B12: Rio Grande do Norte | C12: Nordeste | D12: =COUNTIF(Municipios!$E$2:$E$5572,$A12) -> 167 | E12: =COUNTIF(Distritos!$G$2:$G$10752,$A12) -> 191 | F12: =COUNTIF(Regioes_Imediatas!$F$2:$F$511,$A12) -> 11 | G12: =COUNTIF(Regioes_Intermediarias!$C$2:$C$134,$A12) -> 3 | H12: =COUNTIFS(Municipios!$E$2:$E$5572,$A12,Municipios!$O$2:$O$5572,"IBGE Localidades 2010*") -> 1 | I12: =IF(D12=0,0,E12/D12) -> 1.1437126
A13: PB | B13: Paraíba | C13: Nordeste | D13: =COUNTIF(Municipios!$E$2:$E$5572,$A13) -> 223 | E13: =COUNTIF(Distritos!$G$2:$G$10752,$A13) -> 297 | F13: =COUNTIF(Regioes_Imediatas!$F$2:$F$511,$A13) -> 15 | G13: =COUNTIF(Regioes_Intermediarias!$C$2:$C$134,$A13) -> 4 | H13: =COUNTIFS(Municipios!$E$2:$E$5572,$A13,Municipios!$O$2:$O$5572,"IBGE Localidades 2010*") -> 1 | I13: =IF(D13=0,0,E13/D13) -> 1.3318386
... A28: DF | B28: Distrito Federal | C28: Centro-Oeste | D28: =COUNTIF(Municipios!$E$2:$E$5572,$A28) -> 1 | E28: =COUNTIF(Distritos!$G$2:$G$10752,$A28) -> 1 | F28: =COUNTIF(Regioes_Imediatas!$F$2:$F$511,$A28) -> 1 | G28: =COUNTIF(Regioes_Intermediarias!$C$2:$C$134,$A28) -> 1 | H28: =COUNTIFS(Municipios!$E$2:$E$5572,$A28,Municipios!$O$2:$O$5572,"IBGE Localidades 2010*") -> 0 | I28: =IF(D28=0,0,E28/D28) -> 1
A30: TOTAL BRASIL | D30: =SUM(D2:D28) -> 5571 | E30: =SUM(E2:E28) -> 10751 | F30: =SUM(F2:F28) -> 510 | G30: =SUM(G2:G28) -> 133 | H30: =SUM(H2:H28) -> 15 | I30: =IF(D30=0,0,E30/D30) -> 1.9298151
A32: Todas as colunas numéricas são fórmulas (COUNTIF/COUNTIFS/SUM) sobre as abas de dados. No Power BI, importe a tabela tbl_Resumo_UF (sem a linha de total).

Sheet Auditoria_Coordenadas
A1: Código IBGE | B1: Município | C1: UF | D1: Status da Coordenada | E1: Decisão | F1: Motivo da Inclusão | G1: Latitude Final | H1: Longitude Final | I1: Lat. IBGE 2022 | J1: Lon. IBGE 2022 | K1: Lat. IBGE 2010 | L1: Lon. IBGE 2010 | M1: Lat. Base Independente | N1: Lon. Base Independente | O1: Dist. 2022 x 2010 (km) | P1: Dist. 2022 x Independente (km) | Q1: Dist. 2010 x Independente (km) | R1: Sede dentro do Limite Municipal | S1: Observação
A2: 1100205 | B2: Porto Velho | C2: RO | D2: Corrigida - a conferir | E2: Usado IBGE 2010 (ponto 2022 rejeitado — evidência na observação) | F2: Divergência > 5 km entre fontes. Status diferente de OK. Curadoria documentada. | G2: -8.768892 | H2: -63.831446 | I2: -9.6462 | J2: -63.9599 | K2: -8.768892 | L2: -63.831446 | M2: -8.76077 | N2: -63.8999 | O2: 98.57 | P2: 98.68 | Q2: 7.58 | R2: Sim | S2: Ponto IBGE 2022 (-9,6462; -63,9599) divergia 98,6 km do IBGE 2010 e 98,7 km da base independente; substituído pelo IBGE 2010. O ponto 2022 está isolado (localidade IBGE 2010 mais próxima a 63,5 km). IBGE 2010 x base independente: 7,6 km. O ponto IBGE 2010 fica na Zona Leste da cidade; para análises que exijam o centro, use a coordenada publicada pela Prefeitura. Referência externa — Prefeitura de Porto Velho (8°45'43"S 63°54'14"W, centro): (-8,7619; -63,9039), a 8,0 km do ponto adotado.
A3: 1300706 | B3: Boca do Acre | C3: AM | D3: Corrigida - a conferir | E3: Usado IBGE 2010 (ponto 2022 rejeitado — evidência na observação) | F3: Divergência > 5 km entre fontes. Status diferente de OK. Curadoria documentada. | G3: -8.751243 | H3: -67.399578 | I3: -8.7724 | J3: -67.336 | K3: -8.751243 | L3: -67.399578 | M3: -8.74232 | N3: -67.3919 | O3: 7.37 | P3: 6.99 | Q3: 1.3 | R3: Sim | S3: Ponto IBGE 2022 (-8,7724; -67,3360) divergia 7,4 km do IBGE 2010 e 7,0 km da base independente; substituído pelo IBGE 2010. Fontes divergem ~7 km; o município tem mais de um núcleo urbano.
A4: 4322350 | B4: União da Serra | C4: RS | D4: A conferir | E4: Mantido IBGE 2022, a conferir (ver observação) | F4: Ponto 2022 a ≥ 3 km das duas referências. Status diferente de OK. Sede junto à sede de outro distrito. Curadoria documentada. | G4: -28.7546 | H4: -52.015 | I4: -28.7546 | J4: -52.015 | K4: -28.779899 | L4: -52.000417 | M4: -28.7833 | N4: -52.0238 | O4: 3.15 | P4: 3.3 | Q4: 2.31 | R4: Sim | S4: Ponto IBGE 2022 mantido, mas o IBGE 2010 (-28,7799; -52,0004) fica a 3,2 km e a base independente a 3,3 km dele; entre si, as duas referências distam 2,3 km. Na DTB 2025 o distrito-sede (05) chama-se 'São Luiz' e o distrito 20 'União da Serra'; no IBGE 2010 eram 05 'União da Serra' e 20 'Oeste'. O ponto IBGE 2022 fica junto à sede do distrito 20, ~3,2 km do ponto IBGE 2010 da sede. O ponto da sede fica a 0,21 km da sede do distrito 'União da Serra' (não-sede).
A5: 1302702 | B5: Manicoré | C5: AM | D5: Corrigida | E5: Usado IBGE 2010 (ponto 2022 rejeitado — evidência na observação) | F5: Divergência > 5 km entre fontes. Status diferente de OK. | G5: -5.813205 | H5: -61.299248 | I5: -7.9257 | J5: -61.5645 | K5: -5.813205 | L5: -61.299248 | M5: -5.80462 | N5: -61.2895 | O5: 236.72 | P5: 237.8 | Q5: 1.44 | R5: Sim | S5: Ponto IBGE 2022 (-7,9257; -61,5645) divergia 236,7 km do IBGE 2010 e 237,8 km da base independente; substituído pelo IBGE 2010. O ponto 2022 coincide com Projeto de Assentamento 'Agrovila do PA Santo Antonio do Matupi' (IBGE 2010, a 0,82 km).
A6: 1100130 | B6: Machadinho D'Oeste | C6: RO | D6: Corrigida | E6: Usado IBGE 2010 (ponto 2022 rejeitado — evidência na observação) | F6: Divergência > 5 km entre fontes. Status diferente de OK. | G6: -9.425562 | H6: -61.999593 | I6: -9.4657 | J6: -62.2562 | K6: -9.425562 | L6: -61.999593 | M6: -9.44363 | N6: -61.9818 | O6: 28.5 | P6: 30.2 | Q6: 2.8 | R6: Sim | S6: Ponto IBGE 2022 (-9,4657; -62,2562) divergia 28,5 km do IBGE 2010 e 30,2 km da base independente; substituído pelo IBGE 2010. O ponto 2022 está isolado (localidade IBGE 2010 mais próxima a 20,5 km).
A7: 1101401 | B7: Monte Negro | C7: RO | D7: Corrigida | E7: Usado IBGE 2010 (ponto 2022 rejeitado — evidência na observação) | F7: Divergência > 5 km entre fontes. Status diferente de OK. | G7: -10.263098 | H7: -63.295559 | I7: -10.0375 | J7: -63.3339 | K7: -10.263098 | L7: -63.295559 | M7: -10.2458 | N7: -63.29 | O7: 25.43 | P7: 23.66 | Q7: 2.02 | R7: Sim | S7: Ponto IBGE 2022 (-10,0375; -63,3339) divergia 25,4 km do IBGE 2010 e 23,7 km da base independente; substituído pelo IBGE 2010. O ponto 2022 está isolado (localidade IBGE 2010 mais próxima a 35,7 km).
A8: 1100288 | B8: Rolim de Moura | C8: RO | D8: Corrigida | E8: Usado IBGE 2010 (ponto 2022 rejeitado — evidência na observação) | F8: Divergência > 5 km entre fontes. Status diferente de OK. | G8: -11.722259 | H8: -61.785781 | I8: -11.7251 | J8: -61.5543 | K8: -11.722259 | L8: -61.785781 | M8: -11.7271 | N8: -61.7714 | O8: 25.2 | P8: 23.64 | Q8: 1.66 | R8: Sim | S8: Ponto IBGE 2022 (-11,7251; -61,5543) divergia 25,2 km do IBGE 2010 e 23,6 km da base independente; substituído pelo IBGE 2010. O ponto 2022 coincide com Povoado 'Nova Estrela' (IBGE 2010, a 0,80 km).
A9: 1100072 | B9: Corumbiara | C9: RO | D9: Corrigida | E9: Usado IBGE 2010 (ponto 2022 rejeitado — evidência na observação) | F9: Divergência > 5 km entre fontes. Status diferente de OK. Curadoria documentada. | G9: -12.99752 | H9: -60.948701 | I9: -13.0092 | J9: -61.1279 | K9: -12.99752 | L9: -60.948701 | M9: -12.9551 | N9: -60.8947 | O9: 19.46 | P9: 25.97 | Q9: 7.52 | R9: Sim | S9: Ponto IBGE 2022 (-13,0092; -61,1279) divergia 19,5 km do IBGE 2010 e 26,0 km da base independente; substituído pelo IBGE 2010. O ponto 2022 coincide com Povoado 'Vitória da União' (IBGE 2010, a 0,29 km). IBGE 2010 x base independente: 7,5 km. A base independente aponta para o Povoado Alto Guarajus; o ponto IBGE 2010 é a área urbana (CIDADE) da sede.
A10: 1101476 | B10: Primavera de Rondônia | C10: RO | D10: Corrigida | E10: Usado IBGE 2010 (ponto 2022 rejeitado — evidência na observação) | F10: Divergência > 5 km entre fontes. Status diferente de OK. | G10: -11.825707 | H10: -61.316546 | I10: -11.9749 | J10: -61.3769 | K10: -11.825707 | L10: -61.316546 | M10: -11.8295 | N10: -61.3153 | O10: 17.84 | P10: 17.5 | Q10: 0.44 | R10: Sim | S10: Ponto IBGE 2022 (-11,9749; -61,3769) divergia 17,8 km do IBGE 2010 e 17,5 km da base independente; substituído pelo IBGE 2010. O ponto 2022 coincide com Povoado 'Querência do Norte' (IBGE 2010, a 0,14 km).
A11: 1101484 | B11: São Felipe D'Oeste | C11: RO | D11: Corrigida | E11: Usado IBGE 2010 (ponto 2022 rejeitado — evidência na observação) | F11: Divergência > 5 km entre fontes. Status diferente de OK. | G11: -11.914389 | H11: -61.512508 | I11: -11.8002 | J11: -61.4737 | K11: -11.914389 | L11: -61.512508 | M11: -11.9023 | N11: -61.5026 | O11: 13.38 | P11: 11.78 | Q11: 1.72 | R11: Sim | S11: Ponto IBGE 2022 (-11,8002; -61,4737) divergia 13,4 km do IBGE 2010 e 11,8 km da base independente; substituído pelo IBGE 2010. O ponto 2022 coincide com Povoado 'Novo Paraíso' (IBGE 2010, a 0,09 km).
A12: 1100908 | B12: Castanheiras | C12: RO | D12: Corrigida | E12: Usado IBGE 2010 (ponto 2022 rejeitado — evidência na observação) | F12: Divergência > 5 km entre fontes. Status diferente de OK. | G12: -11.426842 | H12: -61.949161 | I12: -11.5005 | J12: -61.8876 | K12: -11.426842 | L12: -61.949161 | M12: -11.4253 | N12: -61.9482 | O12: 10.59 | P12: 10.66 | Q12: 0.2 | R12: Sim | S12: Ponto IBGE 2022 (-11,5005; -61,8876) divergia 10,6 km do IBGE 2010 e 10,7 km da base independente; substituído pelo IBGE 2010. O ponto 2022 coincide com Povoado 'Jardinópolis' (IBGE 2010, a 0,55 km).
A13: 3541000 | B13: Praia Grande | C13: SP | D13: Corrigida | E13: Usado IBGE 2010 (ponto 2022 rejeitado — evidência na observação) | F13: Divergência > 5 km entre fontes. Status diferente de OK. Curadoria documentada. | G13: -24.003022 | H13: -46.41205 | I13: -24.0307 | J13: -46.4939 | K13: -24.003022 | L13: -46.41205 | M13: -24.0084 | N13: -46.4121 | O13: 8.86 | P13: 8.67 | Q13: 0.6 | R13: Sim | S13: Ponto IBGE 2022 (-24,0307; -46,4939) divergia 8,9 km do IBGE 2010 e 8,7 km da base independente; substituído pelo IBGE 2010. O ponto 2022 está isolado (localidade IBGE 2010 mais próxima a 11,1 km). Referência externa — geodatos.net / Cidade Brasil (centro): (-24,0058; -46,4028), a 1,0 km do ponto adotado.
... A17: 2401008 | B17: Apodi | C17: RN | D17: Corrigida | E17: Usado IBGE 2010 (ponto 2022 arredondado ao minuto de arco) | F17: Ponto 2022 com precisão de minuto. | G17: -5.66377 | H17: -37.797784 | I17: -5.6666 | J17: -37.7999 | K17: -5.66377 | L17: -37.797784 | M17: -5.65349 | N17: -37.7946 | O17: 0.39 | P17: 1.57 | Q17: 1.2 | R17: Sim | S17: Ponto IBGE 2022 (-5,6666; -37,7999) arredondado ao minuto de arco; usado o ponto IBGE 2010, de precisão total, a 0,39 km.
A18: 4119954 | B18: Pontal do Paraná | C18: PR | D18: OK | E18: Mantido IBGE 2022 (nenhuma referência a < 3 km: IBGE 2010 a 11,9 km, base independente a 4,2 km; não houve divergência simultânea > limiar) | F18: Divergência > 5 km entre fontes. | G18: -25.6973 | H18: -48.4784 | I18: -25.6973 | J18: -48.4784 | K18: -25.594151 | L18: -48.448327 | M18: -25.6735 | N18: -48.5111 | O18: 11.86 | P18: 4.21 | Q18: 10.84 | R18: Sim
